/**
 *  @author Yunxiang He
 *  @date Feb 13, 2018 9:15:44 PM
 */

package exceptions;

class _110_ThrowDemo {
    static void demoproc() {
        try {
            throw new NullPointerException("demo");
        } catch (NullPointerException e) {
            System.out.println("Caught inside demoproc.");
            throw e; // re-throw the exception
        }
    }

    public static void main(String[] args) {
        try {
            demoproc();
        } catch (NullPointerException e) {
            System.out.println("Recaught: " + e);
        }
    }
}